Workbook

Sheet QUO
A1: QUOTATION
E2: No. | F2: =VLOOKUP(QUO!G11,Sale!B3:E16,4,0)&"_"&DAY(NOW())&MONTH(NOW())&YEAR(NOW())&"_"&J12 -> RTC05_2242019_122
E3: Date | F3: =TODAY() -> 43577
A5: Company: | C5: =VLOOKUP(I12,Custom!B2:G573,3,0) -> VICCO TECHNOLOGY JOINT STOCK COMPANY | E5: Công ty cổ phần RTC Technology Việt Nam
A6: Add: | C6: =VLOOKUP(I12,Custom!B2:G260,4,0) -> No.27, 332/7/24 Alley, 332 Lane, Hoang Cong Chat St, Phu Dien Ward, Bac Tu Liem Dist, Ha Noi. | E6: RTC Technology Vietnam JSC
A7: Attn: | C7: =VLOOKUP(I12,Custom!B2:G262,2,0) -> Mr.Tùng | E7: Số nhà A52 TT10 KĐT mới Văn Quán, Hà Đông, Hà Nội, Việt Nam
A8: Phone number: | C8: =VLOOKUP(I12,Custom!B2:G261,5,0) -> 0965 170 196 | E8: A52 TT10, Van Quan New Urban Area, Van Quan Ward, Ha Dong Distric, Hanoi, Vietnam
A9: Mail: | C9: =VLOOKUP(I12,Custom!B2:G261,6,0) -> gm@vicotech.vn | E9: Hotmail: RTCtechnology@outlook.com
E10: Website: http://rtc.edu.vn or http://rtctechnology.com.vn
E11: Sales member: | G11: Đỗ Hoa | I11: Mã khách hàng
E12: Phone number: | G12: =VLOOKUP(QUO!G11,Sale!B3:E16,2,0) -> 0399 103 595 | I12: VICCO-Tùng | J12: =VLOOKUP(I12,Custom!B2:H261,7,0) -> 122
E13: Email: | G13: =VLOOKUP(QUO!G11,Sale!B3:E16,3,0) -> dothi.hoa@gmail.com
A15: Quotation include: | E15: Prepair by: | G15: Approved by:
A17: No. | B17: Description/ Model | D17: Quantity | E17: Unit | F17: Unit Price (VND) | G17: Total Price (VND) | H17: Delivery
B19: Bộ xử lý hình ảnh IS8401M-363-50 Bao gồm: | D19: 24 | E19: set/ bộ | F19: 325300000 | G19: =F19*D19 -> 7807200000 | H19: 2-4 weeks | I19: =660*1.15/0.8 -> 948.75
A20: 1 | B20: IS8401M-363-50 | D20: 24 | E20: pcs
B21: IS8401M-363-50 - In-Sight 8401, 1.3MP, with PatMax
A22: 2 | B22: CCB-84901-2001-05 | D22: 24 | E22: pcs
B23: Cognex X-Coded M12 Ethernet Cable (5M Length)
A24: 3 | B24: CCB-M8IO-05 | D24: 24 | E24: pcs
B25: CCB-M8IO-05 - In-Sight Micro Trigger/Strobe Cable, 5 m
A26: 4 | B26: POE | D26: 24 | E26: pcs
A28: 5 | B28: VL-HR4675B | D28: 12 | E28: pcs
B29: Lighting
A30: 6 | B30: VL-HR4675W | D30: 12 | E30: pcs
B31: Lighting
A32: 7 | B32: SV-5014H | D32: 24 | E32: pcs
B33: Lens
A34: 8 | B34: SV-EXR40 | D34: 24 | E34: pcs
B35: Tube
A36: 9 | B36: SV-EXR5 | D36: 24 | E36: pcs
B37: Tube
A38: 10 | B38: VL-EC3POW-05-C2 | D38: 24 | E38: pcs
B39: Controller lighting
A40: TOTAL PRICE (This price is not included VAT) | G40: =SUM(G19:G25) -> 7807200000 | H40: VND | J40: =#REF!/23500 -> #REF! | XFD40: =SUM(G40:XFC40) -> #REF!
A41: VAT | F41: 0.1 | G41: =G40*10% -> 780720000 | H41: VND
A42: TOTAL PAYMENT | G42: =SUM(G40:G41) -> 8587920000 | H42: VND
A43: By words: | C43: Tám tỉ năm trăm tám mươi bảy triệu, chín trăm hai mươi nghìn đồng chẵn./. | J43: total payment
A45: Terms and Conditions
A46: * Delivery and fees: This price is included delivery fee.
...

Sheet Sheet1
F5: giá X1.4
B7: Model | C7: list | D7: disc | E7: disc pr | F7: Price | G7: quarity | H7: Total price | I7: exchange rate | J7: XXX
B8: DMR-303X-00 | C8: 3895 | D8: 41 | E8: 2298.05 | F8: =E8*J8*I8 -> 71285511 | G8: 1 | H8: =G8*F8 -> 71285511 | I8: 23500 | J8: 1.32
B9: DataMan 303X Fixed Mount ID Reader | H9: =G9*F9 -> 0 | I9: 23500 | J9: 1.32
B10: CCB-84901-1003-05 | C10: 125 | D10: 25 | E10: 93.75 | F10: =E10*J10*I10 -> 2908125 | H10: =G10*F10 -> 0 | I10: 23500 | J10: 1.32
B11: Cognex Std. Ethernet Cable, 5M (15') | H11: =G11*F11 -> 0 | I11: 23500 | J11: 1.32
B12: CCB-PWRIO-05 | C12: 140 | E12: 105 | F12: =E12*J12*I12 -> 3257100 | H12: =G12*F12 -> 0 | I12: 23500 | J12: 1.32
B13: Power and I/O Cable, M12-12 (5M Length) | H13: =G13*F13 -> 0 | I13: 23500 | J13: 1.32
F14: =E14*J14*I14 -> 0 | H14: =G14*F14 -> 0 | I14: 23500 | J14: 1.32
H15: =G15*F15 -> 0 | I15: 23500 | J15: 1.32
A16: RFTEC | B16: IS8402M-363-50 | C16: 9025 | E16: =C16*0.6 -> 5415 | F16: =E16*J16*I16 -> 167973300 | G16: 1 | H16: =G16*F16 -> 167973300 | I16: 23500 | J16: 1.32
B17: In-Sight 8402 With PatMax without PatMax Redline | E17: =C17*0.6 -> 0 | F17: =E17*J17*I17 -> 0 | G17: 1 | H17: =G17*F17 -> 0 | I17: 23500 | J17: 1.32
B18: CCB-84901-2001-05 | C18: 125 | E18: =C18*0.6 -> 75 | F18: =E18*J18*I18 -> 2326500 | G18: 1 | H18: =G18*F18 -> 2326500 | I18: 23500 | J18: 1.32
B19: Cognex X-Coded M12 Ethernet Cable (5M Length) | E19: =C19*0.6 -> 0 | F19: =E19*J19*I19 -> 0 | G19: 1 | H19: =G19*F19 -> 0 | I19: 23500 | J19: 1.32
B20: CCB-M8IO-05 | C20: 95 | E20: =C20*0.6 -> 57 | F20: =E20*J20*I20 -> 1768140 | G20: 1 | H20: =G20*F20 -> 1768140 | I20: 23500 | J20: 1.32
B21: In-Sight Micro Trigger/Strobe Cable, 2 m | E21: =C21*0.6 -> 0 | F21: =E21*J21*I21 -> 0 | G21: 1 | H21: =G21*F21 -> 0 | I21: 23500 | J21: 1.32
B22: POE | C22: 20 | E22: 20 | F22: =E22*J22*I22 -> 620400 | G22: 1 | H22: =G22*F22 -> 620400 | I22: 23500 | J22: 1.32
B23: power of ethernet supply unit | F23: =E23*J23*I23 -> 0 | G23: 1 | H23: =G23*F23 -> 0 | I23: 23500 | J23: 1.32
B24: VL-EXC100100W | C24: 250 | E24: 250 | F24: =E24*J24*I24 -> 7755000 | G24: 1 | H24: =G24*F24 -> 7755000 | I24: 23500 | J24: 1.32
B25: Vision lighting | F25: =E25*J25*I25 -> 0 | G25: 1 | H25: =G25*F25 -> 0 | I25: 23500 | J25: 1.32
B26: VL-EC3POW-05-C2 | C26: 30 | E26: 30 | F26: =E26*J26*I26 -> 930600 | G26: 1 | H26: =G26*F26 -> 930600 | I26: 23500 | J26: 1.32
B27: Led Light Controller | F27: =E27*J27*I27 -> 0 | G27: 1 | H27: =G27*F27 -> 0 | I27: 23500 | J27: 1.32
H28: =SUM(H16:H26) -> 181373940
B29: service | H29: 18000000
B30: Total | H30: =SUM(H28:H29) -> 199373940

Sheet Sale
B2: Sales name | C2: Phone | D2: Email | E2: Mã sales
B3: Huyền Trang | C3: 0976 370 489 | D3: sales@rtc.edu.vn | E3: RTC01
B4: Nguyễn Thơm | C4: 0969.394.556 | D4: nguyen.thom@rtc.edu.vn | E4: RTC02
B5: Nguyễn Dũng | C5: 0389961275 | D5: sales01@rtc.edu.vn | E5: RTCCOGNEX1
B6: Lê Hương | C6: 0976 905 549 | D6: le.huong@rtc.edu.vn | E6: RTC04
B7: Đỗ Hoa | C7: 0399 103 595 | D7: dothi.hoa@gmail.com | E7: RTC05
E8: RTC06
E9: RTC07
E10: RTC08
E11: RTC09
E12: RTC10
E13: RTC11
E14: RTC12
E15: RTC13
E16: RTC14

Sheet ĐKHOẢN CHUNG
B2: Điều kiện thương mại. | D2: ĐỊA ĐIỂM GIAO HÀNG
B3: * Delivery and fees: This price is included delivery fee. | D3: * Place of delivery: Door to door of customer
B4: * Delivery and fees:Prices do include shipping costs and in HaNoi. | D4: * Place of delivery: At the company warehouse RTC Technology
B5: * Delivery and fees: The Price includes delivery fee and one-way customs procedures fee
B6: * Delivery and fees: The Price includes one-way customs procedures fee
B7: * Delivery and fees: The Price includes delivery fee.if you buy spare parts, the value is less than 15 million, please pay delivery fee
B10: Điều khoản thanh toán
B11: * Term of Payment : Pay 100% when order
B12: * Payment :100% will be paid after 1 month of receiving the goods
B13: * Payment : Pay 100% when order
B14: * Payment :Deposit 50% of the orders immediately after signing the contract and Payment of 50% of contract value before delivery
B15: * Payment : 50% will be paid in advance, the remain will be paid after 1 weeks of receiving the goods

Sheet Custom
A1: TT | B1: Mã khách hàng | C1: Tên khách hàng | D1: Công ty | E1: Địa chỉ | F1: Số ĐT | G1: Email | H1: STT | I1: SÔ BÁO GIÁ
A2: 15 | B2: 3Q-Ly | C2: MS. Ly | D2: 3Q | E2: Số 5-A1, tổ 23, Xuân Thủy, Cầu Giấy, HN | F2: 963285594 | G2: pur.3qvietnam@gmail.com | H2: =A2 -> 15
A3: 44 | B3: ADI-Phúc | C3: Mr.Phúc | D3: ADI | E3: Trần Khát Chân-Hai Bà Trừng | F3: 0973 581 631 | G3: phucnh@adi-jsc.com | H3: =A3 -> 44
A4: 39 | B4: AJNOMOTO-Việt | C4: Mr Việt | D4: Ajnomoto | F4: 0251 3831 289 (Ext: 564) | G4: viet_nnq@Ajinomoto.com.vn | H4: =A4 -> 39
A5: 10 | B5: ANAM-Hà | C5: Ms.Hà (pur) | D5: Anam | E5: KCN Đồng Văn II - Duy Tiên - Hà Nam | F5: 912347091 | G5: thiha.nguyen@aname.co.kr | H5: =A5 -> 10
A6: 20 | B6: ANS-Nguyên | C6: Ms. Nguyên | D6: Anh Nghi Sơn (ANS) | E6: D3,Dinh Tien Hoang Street, Ward 3, Mieu Noi Resident Area , Binh Thanh Dist , Ho Chi Minh City, Viet Nam | F6: 902 592 090 | G6: nguyen.ans@ansvietnam.com | H6: =A6 -> 20
A7: 31 | B7: APN-Hương | C7: Ms. Hương | D7: Anphanam | E7: Số 95, tổ 5, Kim Quan, P. Việt Hưn, Q. Long Biên, TP Hà Nội. | F7: 904999549 | G7: pur.apn@gmail.com | H7: =A7 -> 31
A8: 83 | B8: ASECO-Kiểm | C8: Mr.Kiểm | D8: CÔNG TY CỔ PHẦN TỰ ĐỘNG HÓA ASECO | E8: Số 6A/109 Đường Quan Nhân, Phường Nhân Chính , Quận Thanh Xuân, HN | F8: 0976777214 | G8: kiempv.aseco@gmail.com | H8: =A8 -> 83
A9: 130 | B9: BAOAN-Lan | C9: Ms.Lan | D9: BẢO AN | E9: Hải Phòng | G9: lanvu.baoan@gmail.com | H9: =A9 -> 130
A10: 129 | B10: BAOAN-Thắng | C10: Mr.Thắng | D10: BẢO AN | E10: Hải Phòng | F10: 0904 446 458 | G10: lethang.baoan@gmail.com | H10: =A10 -> 129
A11: 102 | B11: BIATHANHHOA-Tuấn | C11: Mr.Tuấn | D11: Công ty CP Bia Thanh Hóa | E11: 152 Quang Trung, Ngọc Trạo, Tp.Thanh Hóa, Thanh Hóa | F11: 0903 291 077 | H11: =A11 -> 102
A12: 93 | B12: BSI-Hằng | C12: Ms.Hằng | D12: Công ty TNHH Phát triển Hạ tầng Công nghệ BSI | E12: 2/1 C Cao Thắng, Phường 5, Quận 3, Thành phố Hồ Chí Minh | G12: hanglt1@bsi.vn | H12: =A12 -> 93
A13: 89 | B13: CHYODA-Cần | C13: Mr.Cần | D13: Chiyoda integre Viet Nam co..Ltd | E13: Lô C4- KCN thăng long- Xã kim chung- Huyện đông anh- TP hà nội- Việt Vam | F13: "0976034784 | G13: hoangcancivn@gmail.com | H13: =A13 -> 89
A14: 120 | B14: COMBAT-Chong | C14: Mr.Chong | D14: COMBAT | G14: ckyaw@combat.com.my | H14: =A14 -> 120
A15: 138 | B15: DAEKHON-Kiên | C15: Mr.Kiên | D15: Công ty Daekhon Vina | E15: Tầng 8 -tòa nhà HH3 SUDICO -khu đô thị Mỹ Đình Sông Đà -Phường Mễ Trì -Quận Nam Từ Liêm -Thành Phố Hà Nội -Việt nam | F15: 0981 312 612 | G15: kien@daekhon.co.kr | H15: =A15 -> 138
A16: 128 | B16: DAIKIN-Quỳnh | C16: Mr.Quỳnh | D16: DAIKIN | E16: Hưng Yên | F16: (0) 976 569 846 | G16: nhuquynh.nguyen@daikin.com.vn | H16: =A16 -> 128
A17: 12 | B17: DARAM-Thảo | C17: Ms.Thảo | D17: Daram | E17: Số 99 Phố Thiên Hiền, Mỹ Đình 1, Từ Liêm, Hà Nội | F17: 043 7878923 | G17: thaothao2892@gmail.com | H17: =A17 -> 12
A18: 75 | B18: DENKA-Chinh | C18: Ms.Chinh | D18: Công ty TNHH vật liệu mới DENKA Việt Nam | E18: Lô đất số D-5, KCN Thăng Long II, Xã Liêu Xá, Huyện Yên Mỹ, Tỉnh Hưng Yên, Việt Nam | F18: 0915557815 | H18: =A18 -> 75
A19: 74 | B19: DENKA-Tuấn | C19: Mr.Tuấn | D19: Công ty TNHH vật liệu mới DENKA Việt Nam | E19: Lô đất số D-5, KCN Thăng Long II, Xã Liêu Xá, Huyện Yên Mỹ, Tỉnh Hưng Yên, Việt Nam | F19: 0936422158 | G19: tuan-nguyenthien@denka.com.vn | H19: =A19 -> 74
A20: 7 | B20: DONGYANG-Như | C20: Ms.Như | D20: DongYang | E20: Lô C5-3- KCN Tràng Duệ - Hải Phòng | F20: 975315099 | H20: =A20 -> 7
A21: 40 | B21: ELK-ThuAnh | C21: Ms Thu Anh | D21: ELK VINA | E21: CN2-1, THACH THAT - QUOC OAI INDUSTRIAL ZONE, THACH THAT DIST, HANOI, VIET NAM | F21: +84 971974618 | G21: thuanh.nt@elkvina.com | H21: =A21 -> 40
A22: 87 | B22: EMTEK-Chương | C22: Mr.Chương | D22: Công ty Emtek | E22: Khu Vân Trại , Phường Vân Dương, Tp Bắc Ninh | F22: 096 834 7942 | H22: =A22 -> 87
A23: 85 | B23: EMTEK-Lan | C23: Ms.Lan | D23: Công ty Emtek | E23: Khu Vân Trại , Phường Vân Dương, Tp Bắc Ninh | F23: 01275281111 | G23: nlan8202@gmail.com | H23: =A23 -> 85
A24: 86 | B24: EMTEK-Sơn | C24: Ms.Son | D24: Công ty Emtek | E24: Khu Vân Trại , Phường Vân Dương, Tp Bắc Ninh | F24: 01647497917 | G24: maithison91@gmail.com | H24: =A24 -> 86
A25: 103 | B25: ENKEI-Luyện | C25: Mr.Luyện | D25: Công Ty TNHH Enkei Việt Nam | E25: khu công nghiệp Thăng Long Hà Nội | F25: "988683753 | G25: luyen-nv@enkeivn.com.vn | H25: =A25 -> 103
A26: 104 | B26: ENKEI-Tập | C26: Mr.Tập | D26: Công Ty TNHH Enkei Việt Nam | E26: khu công nghiệp Thăng Long Hà Nội | G26: tap-nd@enkeivn.com.vn | H26: =A26 -> 104
A27: 53 | B27: ESQUEL-Trung | C27: Mr.Trung | D27: Công ty Esquel Việt Nam | E27: KCN Lương Sơn - Hòa Bình | F27: 0984.588.465 | H27: =A27 -> 53
A28: 84 | B28: EST-Nhung | C28: Ms.Nhung | D28: EST Industrial Electrical Service and Trading Co., ltd | E28: 9B, Alley 224, Hoang Mai Str., Hoang Mai Dist., Hanoi. | F28: 01676963037 | G28: purchase-3@est.com.vn | H28: =A28 -> 84
A29: 125 | B29: FCC-Hoài | C29: Mss.Hoài | D29: FCC (VIETNAM) CO.,LTD | E29: A5 Plot, Thang Long Industrial Park, Dong Anh Dist, Ha noi. | F29: 0984 983 870 | G29: qchoaint@fcc-vn.com.vn | H29: =A29 -> 125
A30: 124 | B30: FCC-Tân | C30: Mr.Tân | D30: FCC (VIETNAM) CO.,LTD | E30: A5 Plot, Thang Long Industrial Park, Dong Anh Dist, Ha noi. | F30: 097 618 4516. | G30: qctankm@fcc-vn.com.vn | H30: =A30 -> 124
A31: 6 | B31: FINE-Mai | C31: Ms.Mai | D31: Fine | E31: Số 47, TT9, Văn Phú, Hà Đông, HN | F31: 942489129 | G31: sale02@fintv.com.vn | H31: =A31 -> 6
A32: 95 | B32: FOXCON-Sỹ | C32: Mr.Sỹ | D32: FOXCON BẮC GIANG | E32: Khu công nghiệp Vân Trung và Đình Trám. Bắc Giang (thành phố) | F32: '0166 834 6141 | H32: =A32 -> 95
A33: 94 | B33: FOXCON-Trung | C33: Mr.Trung | D33: FOXCON BẮC GIANG | E33: Khu công nghiệp Vân Trung và Đình Trám. Bắc Giang (thành phố) | F33: 0986231288 | G33: cpe_vn_fixture@mail.foxconn.com | H33: =A33 -> 94
A34: 73 | B34: GOSHU-Tùng | C34: Mr.Tùng | D34: Công ty TNHH Goshu Kohsan (Việt Nam) | E34: Lô P1, khu công nghiệp Thăng Long, huyện Đông Anh, thành phố Hà Nội, Việt Nam | F34: 0913326034 | G34: tung.nh.vn@goshukohsan.com | H34: =A34 -> 73
A35: 13 | B35: HANEL-Tùng | C35: Mr.Tùng (PGD) | D35: Hanel PT | E35: Lot 3, TS8 Street, Tien Son Industrial Zone, Tien Du Dist, Bac Ninh Prov, Vietnam | F35: 0985 739 333 | G35: tranductung@hanelpt.com.vn | H35: =A35 -> 13
A36: 97 | B36: HATHU-Dũng | C36: Mr.Dũng | D36: CÔNG TY TNHH HÀ THU | E36: Số nhà 253, đường Phan Chu Trinh,phường Khai Quang, Tp. Vĩnh Yên, Vĩnh Phúc | F36: 0983 871 646 | H36: =A36 -> 97 | I36: RTC/MEIKO-03
A37: 26 | B37: HEESUNG-Hào | C37: Mr Hào | D37: Heesung | E37: Lô G1, KCN Tràng Duệ, thuộc khu kinh tế Đình Vũ - Cát Hải, huyện An Dương, Hải Phòng | F37: 0938 884 625 | G37: khanh.pham@hsnw.co.kr | H37: =A37 -> 26
A38: 55 | B38: HNT-Hòa | C38: Ms Hòa | D38: Công ty TNHH HNT Vina | E38: Khu công nghiệp Lương Sơn, Km36, Quốc lộ 6, xã Hòa Sơn, huyện Lương Sơn, tỉnh Hòa Bình. | F38: 0967 500 524 | G38: nguyenthihoa93@coasia.com | H38: =A38 -> 55
A39: 16 | B39: HNT-Yến | C39: Ms.Yến (pur) | D39: HNT | E39: Luong Son Industrial Park, Hoa Binh, QL6, tt. Lương Sơn, Lương Sơn, Hòa Bình | F39: 974578205 | G39: tranthihaiyen@coasia.com | H39: =A39 -> 16
A40: 18 | B40: HST-Hòa | C40: Mr.Hòa | D40: Công nghệ giải pháp Hà Nội | E40: Phòng C6-05, toà nhà Golden West, Số 2 Lê Văn Thiêm, Q Thanh Xuân, Tp Hà Nội | F40: 0902 384 268 | G40: sale2@hstcorp.vn | H40: =A40 -> 18
...

Sheet Sheet2
A1: Tối đa đặt cọc 30-50%, còn lại thanh toán sau 15 ngày
